Workbook

Sheet Summary of results
E1: Tumble Dryer Performance Test | M1: Form No….................: Rev No/Rev Date…...: Release Date….........:
B7: Identification of machine | F7: Label declaration
J8: NEL | K8: OEL
B9: PRODUCT | C9: ='Table tests'!E5 -> CB & HMD | F9: ENERGY CONSUMPTION [ kWh/100 | kWh/year] | J9: ='Table tests'!M7 -> 110 | K9: ='Table tests'!L7 -> 204
B10: BRAND | C10: ='Table tests'!E7 -> Haier | F10: ENERGY CLASS | J10: ='Table tests'!M5 -> C | K10: ='Table tests'!L5 -> A+++
B11: MODEL | C11: ='Table tests'!AN4 -> 0 | F11: CONDENSATION EFFICIENCY | J11: ='Table tests'!S5 -> 88 | K11: ='Table tests'!S5 -> 88
B12: CODE | C12: ='Table tests'!O11 -> 0 | F12: CONDENSATION CLASS | J12: ='Table tests'!S7 -> B | K12: ='Table tests'!R7 -> 0
B13: TYPE | C13: ='Table tests'!H7 -> HP | D13: HEAT PUMP | F13: FULL LOAD CYCLE TIME [min] | J13: ='Table tests'!L9 -> 205 | K13: ='Table tests'!L9 -> 205
B14: LOAD [kg] | C14: ='Table tests'!H5 -> 9 | D14: 10 | F14: TESTS COMPLETION DATE [dd/mm/yyyy] | J14: =MAX('Table tests'!D21:D32,'Table tests'!D108:D111) -> 46120
B16: Main features
B22: Standard Energy consumption
B23: c | C23: SAEc | E23: Load | G23: Full | H23: Half | J23: Weighted cond. Effi.[%] (New-Old)
B24: =C14 -> 9 | C24: =IF(C13="Vented",0.46*POWER(B24,0.63)*(1-(0.24*G25+0.76*H25)/60-0.0083),0.46*POWER(B24,0.63)) -> 1.8362449 | E24: Energy [kWh] | G24: ='Table tests'!N98 -> 2.1801718 | H24: ='Table tests'!N113 -> #DIV/0! | M24: Off mode | N24: Left mode
B25: Standard Annual Energy cons. (OEL) | E25: Time [min] | G25: =+'Table tests'!O98 -> 307.30848 | H25: =+'Table tests'!O113 -> #DIV/0! | J25: =(+G26*0.24+H26*0.76) -> #DIV/0! | K25: =(+G26*3+H26*4)/7 -> #DIV/0! | M25: 0.5 | N25: 0.5
B26: c | C26: SAEc | E26: Condensing efficiency [%] | G26: =+'Table tests'!P98 -> 86.918222 | H26: =+'Table tests'!P113 -> #DIV/0!
B27: =C14 -> 9 | C27: =IF(C13="Vented",140*POWER(B27,0.8)-(30*(3*G25+4*H25)/420),140*POWER(B27,0.8)) -> 811.93646
B33: Energy consumption | E33: Energy Efficiency Index
B34: Etc = | C34: =0.24*G24+0.76*H24 -> #DIV/0! | E34: EEi = | F34: =100*C34/C24 -> #DIV/0! | J34: AEc = | K34: =160*(3*G24+4*H24)/7+(M25+N25)*(525600-(+G25*3+H25*4)/7*160)/120000 -> #DIV/0! | M34: EEi = | N34: =100*K34/C27 -> #DIV/0!
B36: Etc | C36: INDEX | D36: Energy class | E36: Tolerances | J36: AEc | K36: INDEX | L36: Energy class | M36: Tolerances
B37: =+C$24*43/100 -> 0.78958533 | C37: <43 | D37: A | E37: =+(C$34-B37)/B37 -> #DIV/0! | F37: =+B37/C$24 -> 0.43 | J37: =+C$27*24/100 -> 194.86475 | K37: <24 | L37: A+++ | M37: =+(K$34-J37)/J37 -> #DIV/0! | N37: 0.24
B38: =+C$24*50/100 -> 0.91812247 | C38: <50 | D38: B | E38: =+(C$34-B38)/B38 -> #DIV/0! | F38: =+B38/C$24 -> 0.5 | J38: =+C$27*32/100 -> 259.81967 | K38: <32 | L38: A++ | M38: =+(K$34-J38)/J38 -> #DIV/0! | N38: 0.32
B39: =+C$24*60/100 -> 1.101747 | C39: <60 | D39: C | E39: =+(C$34-B39)/B39 -> #DIV/0! | F39: =+B39/C$24 -> 0.6 | J39: =+C$27*42/100 -> 341.01331 | K39: <42 | L39: A+ | M39: =+(K$34-J39)/J39 -> #DIV/0! | N39: 0.42
B40: =+C$24*70/100 -> 1.2853715 | C40: <70 | D40: D | E40: =+(C$34-B40)/B40 -> #DIV/0! | F40: =+B40/C$24 -> 0.7 | J40: =+C$27*65/100 -> 527.7587 | K40: <65 | L40: A | M40: =+(K$34-J40)/J40 -> #DIV/0! | N40: 0.65
B41: =+C$24*85/100 -> 1.5608082 | C41: <85 | D41: E | E41: =+(C$34-B41)/B41 -> #DIV/0! | F41: =+B41/C$24 -> 0.85 | J41: =+C$27*76/100 -> 617.07171 | K41: <76 | L41: B | M41: =+(K$34-J41)/J41 -> #DIV/0! | N41: 0.76
B42: =+C$24*100/100 -> 1.8362449 | C42: <100 | D42: F | E42: =+(C$34-B42)/B42 -> #DIV/0! | F42: =+B42/C$24 -> 1 | J42: =+C$27*85/100 -> 690.14599 | K42: <85 | L42: C | M42: =+(K$34-J42)/J42 -> #DIV/0! | N42: 0.85
B43: =+C$24*100/100 -> 1.8362449 | C43: >100 | D43: G | E43: =+(C$34-B43)/B43 -> #DIV/0! | F43: =+B43/C$24 -> 1
B45: Summary of results | J45: Summary of results (OEL)
E47: Declared | F47: Measured | G47: Tolerance | H47: Check | M47: Declared | N47: Measured | O47: Tolerance | P47: Check
B48: Energy consumption | E48: =J9 -> 110 | F48: =C34*100 -> #DIV/0! | G48: =(F48-E48)/E48 -> #DIV/0! | H48: =IF(G48<0.06,"OK","NOT OK") -> #DIV/0! | J48: Energy consumption | M48: ='Table tests'!L7 -> 204 | N48: =K34 -> #DIV/0! | O48: =(N48-M48)/M48 -> #DIV/0! | P48: =IF(O48<0.06,"OK","NOT OK") -> #DIV/0!
B49: Condensation efficiency | E49: =J11 -> 88 | F49: =J25 -> #DIV/0! | G49: =(E49-F49)/E49 -> #DIV/0! | H49: =IF(G49<0.06,"OK","NOT OK") -> #DIV/0! | J49: Condensation efficiency | M49: =K11 -> 88 | N49: =K25 -> #DIV/0! | O49: =(M49-N49)/M49 -> #DIV/0! | P49: =IF(O49<0.06,"OK","NOT OK") -> #DIV/0!
B50: Full load cycle time [min] | E50: =J13 -> 205 | F50: =G25 -> 307.30848 | G50: =(F50-E50)/E50 -> 0.49906575 | H50: =IF(G50<0.06,"OK","NOT OK") -> NOT OK | J50: Full load cycle time [min] | M50: =J13 -> 205 | N50: =G25 -> 307.30848 | O50: =(N50-M50)/M50 -> 0.49906575 | P50: =IF(O50<0.06,"OK","NOT OK") -> NOT OK
G51: max +6% | O51: max +6%

Sheet Table tests
G2: Insert machine NO# in Lab
B3: ENERGY LABEL | G3: TD2647 | U3: Configuration
D4: check TD info | G4: check TD info | L4: OEL | M4: NEL | U4: Goal:
D5: PRODUCT | E5: CB & HMD | G5: LOAD (kg) | H5: 9 | J5: CLASS | L5: A+++ | M5: C | O5: CONDENSATION | S5: {=IF(E5="CB & HMD",INDEX('TD info'!C18:AB18,MATCH(1,('TD info'!$C$4:$AB$4=H5)*('TD info'!$C$5:$AB$5=M5),0)),"")& IF(E5="CHG",INDEX('TD info'!C49:AB49,MATCH(1,('TD info'!C35:AB35=H5)*('TD info'!C36:AB36=M5),0)),"")& IF(E5="GP",INDEX('TD info'!C80:K80,MATCH(1,('TD info'!C66:K66=H5)*('TD info'!C67:K67=M5),0)),"")& IF(E5="Slim",INDEX('TD info'!C107:F107,MATCH(1,('TD info'!C91:F91=H5)*('TD info'!C93:F93=M5),0)),"")& IF(E5="Cond",INDEX('TD info'!C140:G140,MATCH(1,('TD info'!C124:G124=H5)*('TD info'!C126:G126=M5),0)),"")} -> 88
L6: kWh/ann. | M6: kWh/100 | R6: OEL | S6: NEL | U6: Rear Cover
D7: BRAND | E7: Haier | G7: TYPE | H7: HP | J7: ENERGY | L7: {=IF(E5="CB & HMD",INDEX('TD info'!$C$9:$AB$9,MATCH(1,('TD info'!$C$4:$AB$4=H5)*('TD info'!$C$5:$AB$5=M5),0)),"")& IF(E5="CHG",INDEX('TD info'!C40:AB40,MATCH(1,('TD info'!C35:AB35=H5)*('TD info'!C36:AB36=M5),0)),"")& IF(E5="GP",INDEX('TD info'!C71:K71,MATCH(1,('TD info'!C66:K66=H5)*('TD info'!C67:K67=M5),0)),"")& IF(E5="Slim",INDEX('TD info'!C94:F94,MATCH(1,('TD info'!C91:F91=H5)*('TD info'!C93:F93=M5),0)),"")& IF(E5="Cond",INDEX('TD info'!C127:G127,MATCH(1,('TD info'!C124:G124=H5)*('TD info'!C126:G126=M5),0)),"")& IF(E5="Vent EU",INDEX('TD info'!C160:G160,MATCH(1,('TD info'!C157:G157=H5)*('TD info'!C159:G159=M5),0)),"")& IF(E5="Vent UK",INDEX('TD info'!H160:L160,MATCH(1,('TD info'!H157:L157=H5)*('TD info'!H159:L159=M5),0)),"")} -> 204 | M7: {=IF(E5="CB & HMD",INDEX('TD info'!C7:AB7,MATCH(1,('TD info'!$C$4:$AB$4=H5)*('TD info'!$C$5:$AB$5=M5),0)),"")& IF(E5="CHG",INDEX('TD info'!C38:AB38,MATCH(1,('TD info'!C35:AB35=H5)*('TD info'!C36:AB36=M5),0)),"")& IF(E5="GP",INDEX('TD info'!C69:K69,MATCH(1,('TD info'!C66:K66=H5)*('TD info'!C67:K67=M5),0)),"")& IF(E5="Slim",INDEX('TD info'!C96:F96,MATCH(1,('TD info'!C91:F91=H5)*('TD info'!C93:F93=M5),0)),"")& IF(E5="Cond",INDEX('TD info'!C129:G129,MATCH(1,('TD info'!C124:G124=H5)*('TD info'!C126:G126=M5),0)),"")& IF(E5="Vent EU",INDEX('TD info'!C162:G162,MATCH(1,('TD info'!C157:G157=H5)*('TD info'!C159:G159=M5),0)),"")& IF(E5="Vent UK",INDEX('TD info'!H162:L162,MATCH(1,('TD info'!H157:L157=H5)*('TD info'!H159:L159=M5),0)),"")} -> 110 | O7: COND. CLASS | S7: {=IF(E5="CB & HMD",INDEX('TD info'!C17:AB17,MATCH(1,('TD info'!$C$4:$AB$4=H5)*('TD info'!$C$5:$AB$5=M5),0)),"")& IF(E5="CHG",INDEX('TD info'!C48:AB48,MATCH(1,('TD info'!C35:AB35=H5)*('TD info'!C36:AB36=M5),0)),"")& IF(E5="GP",INDEX('TD info'!C79:K79,MATCH(1,('TD info'!C66:K66=H5)*('TD info'!C67:K67=M5),0)),"")& IF(E5="Slim",INDEX('TD info'!C106:F106,MATCH(1,('TD info'!C91:F91=H5)*('TD info'!C93:F93=M5),0)),"")& IF(E5="Cond",INDEX('TD info'!C140:G140,MATCH(1,('TD info'!C124:G124=H5)*('TD info'!C126:G126=M5),0)),"")} -> B | U7: Motor
U8: Capacitor
D9: TESTED BY | E9: Efe | J9: TIME | L9: {=IF(E5="CB & HMD",INDEX('TD info'!C14:AB14,MATCH(1,('TD info'!$C$4:$AB$4=H5)*('TD info'!$C$5:$AB$5=M5),0)),"")& IF(E5="CHG",INDEX('TD info'!C45:AB45,MATCH(1,('TD info'!C35:AB35=H5)*('TD info'!C36:AB36=M5),0)),"")& IF(E5="GP",INDEX('TD info'!C76:K76,MATCH(1,('TD info'!C66:K66=H5)*('TD info'!C67:K67=M5),0)),"")& IF(E5="Slim",INDEX('TD info'!C102:F102,MATCH(1,('TD info'!C91:F91=H5)*('TD info'!C93:F93=M5),0)),"")& IF(E5="Cond",INDEX('TD info'!C135:G135,MATCH(1,('TD info'!C124:G124=H5)*('TD info'!C126:G126=M5),0)),"")& IF(E5="Vent EU",INDEX('TD info'!C168:G168,MATCH(1,('TD info'!C157:G157=H5)*('TD info'!C159:G159=M5),0)),"")& IF(E5="Vent UK",INDEX('TD info'!H168:L168,MATCH(1,('TD info'!H157:L157=H5)*('TD info'!H159:L159=M5),0)),"")} -> 205 | M9: min | O9: NOISE dB | Class | R9: {=IF(E5="CB & HMD",INDEX('TD info'!C21:AB21,MATCH(1,('TD info'!$C$4:$AB$4=H5)*('TD info'!$C$5:$AB$5=M5),0)),"")& IF(E5="CHG",INDEX('TD info'!C52:AB52,MATCH(1,('TD info'!C35:AB35=H5)*('TD info'!C36:AB36=M5),0)),"")& IF(E5="GP",INDEX('TD info'!C83:K83,MATCH(1,('TD info'!C66:K66=H5)*('TD info'!C67:K67=M5),0)),"")& IF(E5="Slim",INDEX('TD info'!C110:F110,MATCH(1,('TD info'!C91:F91=H5)*('TD info'!C93:F93=M5),0)),"")& IF(E5="Cond",INDEX('TD info'!C143:G143,MATCH(1,('TD info'!C124:G124=H5)*('TD info'!C126:G126=M5),0)),"")& IF(E5="Vent EU",INDEX('TD info'!C176:G176,MATCH(1,('TD info'!C157:G157=H5)*('TD info'!C159:G159=M5),0)),"")& IF(E5="Vent UK",INDEX('TD info'!H176:L176,MATCH(1,('TD info'!H157:L157=H5)*('TD info'!H159:L159=M5),0)),"")} -> 63 | S9: {=IF(E5="CB & HMD",INDEX('TD info'!C22:AB22,MATCH(1,('TD info'!$C$4:$AB$4=H5)*('TD info'!$C$5:$AB$5=M5),0)),"")& IF(E5="CHG",INDEX('TD info'!C53:AB53,MATCH(1,('TD info'!C35:AB35=H5)*('TD info'!C36:AB36=M5),0)),"")& IF(E5="GP",INDEX('TD info'!C84:K84,MATCH(1,('TD info'!C66:K66=H5)*('TD info'!C67:K67=M5),0)),"")& IF(E5="Slim",INDEX('TD info'!C111:F111,MATCH(1,('TD info'!C91:F91=H5)*('TD info'!C93:F93=M5),0)),"")& IF(E5="Cond",INDEX('TD info'!C144:G144,MATCH(1,('TD info'!C124:G124=H5)*('TD info'!C126:G126=M5),0)),"")& IF(E5="Vent EU",INDEX('TD info'!C177:G177,MATCH(1,('TD info'!C157:G157=H5)*('TD info'!C159:G159=M5),0)),"")& IF(E5="Vent UK",INDEX('TD info'!H177:L177,MATCH(1,('TD info'!H157:L157=H5)*('TD info'!H159:L159=M5),0)),"")} -> B | U9: Basement
U10: Compress.
G11: MODEL | N11: CODE | U11: Evap.
U12: Cond.
U13: Capillary
U14: EEPROM
D15: Full load | U15: Main SW
U16: Other
E17: START | H17: DRYING CYCLE
E18: load | H18: measured | M18: normalized
C19: run | D19: date | E19: initial | F19: spinned | G19: efficiency | H19: dried | I19: μ_f | J19: energy | K19: time | L19: water | M19: targ | N19: energy | O19: time | P19: water | Q19: Load | R19: H2O temp | S19: Test Bench | T19: Rpm | U19: End condition | V19: Tangling | W19: Note
E20: g | F20: g | G20: % | H20: g | I20: % | J20: kWh | K20: min | L20: g | M20: % | N20: kWh | O20: min | P20: % | Q20: No | R20: C°
B21: X | C21: 1 | D21: 46091 | E21: 620 | F21: 1092 | G21: =(+(F21-E21)/E21*100) -> 76.129032 | H21: 618 | I21: =(+(H21-E21)/E21*100) -> -0.32258065 | J21: 0.346 | K21: 59 | L21: 0 | M21: 0 | N21: =+J21*((60)*H$5*1000/((G21-I21)*E21)) -> 3.9417722 | O21: =+K21*(60)*H$5*1000/((G21-I21)*E21) -> 672.1519 | P21: =+L21/(F21-H21)*100 -> 0 | Q21: Scrap | R21: X | S21: 5A | T21: X | U21: X | V21: X | W21: havlu(1200 devir sıkma)
B22: X | C22: 2 | D22: 46092 | E22: 1908 | F22: 3096 | G22: =IF(E22="","",(+(F22-E22)/E22*100)) -> 62.264151 | H22: 1868 | I22: =IF(E22="","",(+(H22-E22)/E22*100)) -> -2.0964361 | J22: 0.477 | K22: 74 | L22: 1198 | M22: 0 | N22: =IF(E22="","",(+J22*((60)*H$5*1000/((G22-I22)*E22)))) -> 2.097557 | O22: =IF(E22="","",(+K22*(60)*H$5*1000/((G22-I22)*E22))) -> 325.40717 | P22: =IF(E22="","",(+L22/(F22-H22)*100)) -> 97.557003 | Q22: Scrap | R22: X | S22: 5-A | T22: X | U22: X | V22: X | W22: havlu(1200 devir sıkma)
B23: X | C23: 3 | D23: 46092 | E23: 3080 | F23: 5002 | G23: =IF(E23="","",(+(F23-E23)/E23*100)) -> 62.402597 | H23: 3018 | I23: =IF(E23="","",(+(H23-E23)/E23*100)) -> -2.012987 | J23: 0.704 | K23: 104 | L23: 1888 | M23: 0 | N23: =IF(E23="","",(+J23*((60)*H$5*1000/((G23-I23)*E23)))) -> 1.916129 | O23: =IF(E23="","",(+K23*(60)*H$5*1000/((G23-I23)*E23))) -> 283.06452 | P23: =IF(E23="","",(+L23/(F23-H23)*100)) -> 95.16129 | Q23: Scrap | R23: X | S23: 5-A | T23: X | U23: X | V23: X | W23: havlu(1200 devir sıkma)
B24: X | C24: 4 | D24: 46093 | E24: 4340 | F24: 6760 | G24: =(+(F24-E24)/E24*100) -> 55.760369 | H24: 4335 | I24: =(+(H24-E24)/E24*100) -> -0.11520737 | J24: 0.744 | K24: 102 | L24: 2288 | M24: 0 | N24: =+J24*((60)*H$5*1000/((G24-I24)*E24)) -> 1.6567423 | O24: =+K24*(60)*H$5*1000/((G24-I24)*E24) -> 227.13402 | P24: =+L24/(F24-H24)*100 -> 94.350515 | Q24: Scrap | R24: 15.25 | S24: 5-A | T24: X | U24: X | V24: X | W24: havlu(1200 devir sıkma)
B25: X | C25: 5 | D25: 46093 | E25: 5680 | F25: 8780 | G25: =(+(F25-E25)/E25*100) -> 54.577465 | H25: 5715 | I25: =(+(H25-E25)/E25*100) -> 0.61619718 | J25: 0.898 | K25: 118 | L25: 2854 | M25: 0 | N25: =+J25*((60)*H$5*1000/((G25-I25)*E25)) -> 1.5821207 | O25: =+K25*(60)*H$5*1000/((G25-I25)*E25) -> 207.8956 | P25: =+L25/(F25-H25)*100 -> 93.115824 | Q25: Scrap | R25: X | S25: 5-A | T25: X | U25: X | V25: X | W25: havlu(1200 devir sıkma)
B26: X | C26: 6 | D26: 46094 | E26: 6870 | F26: 11006 | G26: =(+(F26-E26)/E26*100) -> 60.203785 | H26: 8106 | I26: =(+(H26-E26)/E26*100) -> 17.991266 | J26: 0.898 | K26: 118 | L26: 2854 | M26: 0 | N26: =+J26*((60)*H$5*1000/((G26-I26)*E26)) -> 1.6721379 | O26: =+K26*(60)*H$5*1000/((G26-I26)*E26) -> 219.72414 | P26: =+L26/(F26-H26)*100 -> 98.413793 | Q26: Scrap | R26: X | S26: 5-A | T26: X | U26: X | V26: X | W26: havlu(1100 devir sıkma)
B27: X | C27: 7 | D27: 46098 | E27: 8135 | F27: 13005 | G27: =(+(F27-E27)/E27*100) -> 59.864782 | H27: 8034 | I27: =(+(H27-E27)/E27*100) -> -1.2415489 | J27: 1.615 | K27: 203 | L27: 4558 | M27: 0 | N27: =+J27*((60)*H$5*1000/((G27-I27)*E27)) -> 1.7543754 | O27: =+K27*(60)*H$5*1000/((G27-I27)*E27) -> 220.51901 | P27: =+L27/(F27-H27)*100 -> 91.691813 | Q27: Scrap | R27: X | S27: 5-A | T27: X | U27: X | V27: X | W27: havlu(1400 devir sıkma)
B28: X | C28: 8 | D28: 46104 | E28: 9020 | F28: 13825 | G28: =(+(F28-E28)/E28*100) -> 53.27051 | H28: 8880 | I28: =(+(H28-E28)/E28*100) -> -1.5521064 | J28: 1.617 | K28: 204 | L28: 4540 | M28: 0 | N28: =+J28*((60)*H$5*1000/((G28-I28)*E28)) -> 1.7657836 | O28: =+K28*(60)*H$5*1000/((G28-I28)*E28) -> 222.77048 | P28: =+L28/(F28-H28)*100 -> 91.809909 | Q28: Scrap | R28: X | S28: 5-A | T28: X | U28: X | V28: X | W28: havlu(1400 devir sıkma) - sıkma devri azaltılabilir
B29: X | C29: 9 | D29: 46105 | E29: 1248 | F29: 2000 | G29: =(+(F29-E29)/E29*100) -> 60.25641 | H29: 1240 | I29: =(+(H29-E29)/E29*100) -> -0.64102564 | J29: 0.382 | K29: 61 | L29: 826 | M29: 0 | N29: =+J29*((60)*H$5*1000/((G29-I29)*E29)) -> 2.7142105 | O29: =+K29*(60)*H$5*1000/((G29-I29)*E29) -> 433.42105 | P29: =+L29/(F29-H29)*100 -> 108.68421 | Q29: Scrap | R29: X | S29: 5-A | T29: X | U29: X | V29: X | W29: 2 Havlu + çarşaf + yastık kılıfı(1200 devir sıktırma)
B30: X | C30: 10 | D30: 46105 | E30: 2494 | F30: 4012 | G30: =(+(F30-E30)/E30*100) -> 60.866079 | H30: 2478 | I30: =(+(H30-E30)/E30*100) -> -0.6415397 | J30: 0.619 | K30: 92 | L30: 1448 | M30: 0 | N30: =+J30*((60)*H$5*1000/((G30-I30)*E30)) -> 2.1790091 | O30: =+K30*(60)*H$5*1000/((G30-I30)*E30) -> 323.85919 | P30: =+L30/(F30-H30)*100 -> 94.393742 | Q30: Scrap | R30: X | S30: 5-A | T30: X | U30: X | V30: X | W30: 5 havlu + 2 çarşaf + 2 yastık kılıfı (1200 devir sıktırma)
B31: X | C31: 11 | D31: 46120 | E31: 3765 | F31: 6000 | G31: =(+(F31-E31)/E31*100) -> 59.36255 | H31: 3848 | I31: =(+(H31-E31)/E31*100) -> 2.2045153 | J31: 0.7632 | K31: 117 | L31: 1728 | M31: 0 | N31: =+J31*((60)*H$5*1000/((G31-I31)*E31)) -> 1.9150929 | O31: =+K31*(60)*H$5*1000/((G31-I31)*E31) -> 293.58736 | P31: =+L31/(F31-H31)*100 -> 80.297398 | Q31: Scrap | R31: X | S31: 5-A | T31: X | U31: X | V31: X | W31: 4 kılıf+3 çarşaf+8 havlu (1200 devir sıktırma)
B32: X | C32: 12 | D32: 46106 | E32: 5035 | F32: 8026 | G32: =(+(F32-E32)/E32*100) -> 59.404171 | H32: 5014 | I32: =(+(H32-E32)/E32*100) -> -0.41708044 | J32: 1.655 | K32: 144 | L32: 2938 | M32: 0 | N32: =+J32*((60)*H$5*1000/((G32-I32)*E32)) -> 2.9671315 | O32: =+K32*(60)*H$5*1000/((G32-I32)*E32) -> 258.16733 | P32: =+L32/(F32-H32)*100 -> 97.543161 | Q32: Scrap | R32: X | S32: 5-A | T32: X | U32: X | V32: X | W32: 4 klılıf + 4 çarşaf+ 12 havlu (1200 devir sıktırma)
B33: X | C33: 13 | D33: 46106 | E33: 6278 | F33: 10002 | G33: =(+(F33-E33)/E33*100) -> 59.318254 | H33: 6346 | I33: =(+(H33-E33)/E33*100) -> 1.0831475 | J33: 1.219 | K33: 159 | L33: 3376 | M33: 0 | N33: =+J33*((60)*H$5*1000/((G33-I33)*E33)) -> 1.8004923 | O33: =+K33*(60)*H$5*1000/((G33-I33)*E33) -> 234.84683 | P33: =+L33/(F33-H33)*100 -> 92.341357 | Q33: Scrap | R33: X | S33: 5-A | T33: X | U33: X | V33: X | W33: 5 klılıf + 5 çarşaf+ 15 havlu (1200 devir sıktırma)
B34: X | C34: 14 | D34: 46108 | E34: 8050 | F34: 12054 | G34: =(+(F34-E34)/E34*100) -> 49.73913 | H34: 7966 | I34: =(+(H34-E34)/E34*100) -> -1.0434783 | J34: 1.4561 | K34: 189 | L34: 3628 | M34: 0 | N34: =+J34*((60)*H$5*1000/((G34-I34)*E34)) -> 1.9234198 | O34: =+K34*(60)*H$5*1000/((G34-I34)*E34) -> 249.65753 | P34: =+L34/(F34-H34)*100 -> 88.747554 | Q34: Scrap | R34: X | S34: 5-A | T34: X | U34: X | V34: X | W34: 5 çarşaf+7kılıf+29 havlu (1200 devir sıktırma)
B35: X | C35: 15 | D35: 46108 | E35: 928 | F35: 1486 | G35: =(+(F35-E35)/E35*100) -> 60.12931 | H35: 948 | I35: =(+(H35-E35)/E35*100) -> 2.1551724 | J35: 0.28888 | K35: 49 | L35: 600 | M35: 0 | N35: =+J35*((60)*H$5*1000/((G35-I35)*E35)) -> 2.899539 | O35: =+K35*(60)*H$5*1000/((G35-I35)*E35) -> 491.82156 | P35: =+L35/(F35-H35)*100 -> 111.52416 | Q35: Scrap | R35: X | S35: 5-A | T35: X | U35: X | V35: X | W35: 1 çarşaf + 1 kılıf (1200 devir sıktırma)
B36: X | C36: 16 | D36: 46111 | E36: 1586 | F36: 2538 | G36: =(+(F36-E36)/E36*100) -> 60.025221 | H36: 1584 | I36: =(+(H36-E36)/E36*100) -> -0.1261034 | J36: 0.441 | K36: 68 | L36: 864 | M36: 0 | N36: =+J36*((60)*H$5*1000/((G36-I36)*E36)) -> 2.4962264 | O36: =+K36*(60)*H$5*1000/((G36-I36)*E36) -> 384.90566 | P36: =+L36/(F36-H36)*100 -> 90.566038 | Q36: Scrap | R36: X | S36: 5-A | T36: X | U36: X | V36: X | W36: 1 çarşaf + 1 kılıf + 4 havlu (1200 devir sıktırma)
... B56: X | C56: 36 | D56: 46127 | E56: 2180 | F56: 3504 | G56: =(+(F56-E56)/E56*100) -> 60.733945 | H56: 2172 | I56: =(+(H56-E56)/E56*100) -> -0.36697248 | J56: 0.574 | K56: 83 | L56: 1238 | M56: 0 | N56: =+J56*((60)*H$5*1000/((G56-I56)*E56)) -> 2.327027 | O56: =+K56*(60)*H$5*1000/((G56-I56)*E56) -> 336.48649 | P56: =+L56/(F56-H56)*100 -> 92.942943 | Q56: Scrap | R56: X | S56: 5-A | T56: X | U56: X | V56: X | W56: 2 ÇARŞAF+2KIIF+3HAVLU (1200 DEVİR SIKMA AZALTILMALI) 25-27 DERECE
C57: 37 | D57: 46128 | E57: 2485 | F57: 4365 | G57: =(+(F57-E57)/E57*100) -> 75.653924 | H57: 2436 | I57: =(+(H57-E57)/E57*100) -> -1.971831 | J57: 1.46 | K57: 215 | L57: 1830 | M57: 0 | N57: =+J57*((60)*H$5*1000/((G57-I57)*E57)) -> 4.0870918 | O57: =+K57*(60)*H$5*1000/((G57-I57)*E57) -> 601.86625 | P57: =+L57/(F57-H57)*100 -> 94.867807 | Q57: Scrap | R57: X | S57: 5-A | T57: X | U57: X | V57: X | W57: 2 ÇARŞAF+2KIIF+6HAVLU (1000 DEVİR) ANOMALİ VAR
B58: X | C58: 38 | D58: 46129 | E58: 2520 | F58: 4018 | G58: =(+(F58-E58)/E58*100) -> 59.444444 | H58: 2680 | I58: =(+(H58-E58)/E58*100) -> 6.3492063 | J58: 0.55253 | K58: 84 | L58: 1048 | M58: 0 | N58: =+J58*((60)*H$5*1000/((G58-I58)*E58)) -> 2.2299417 | O58: =+K58*(60)*H$5*1000/((G58-I58)*E58) -> 339.01345 | P58: =+L58/(F58-H58)*100 -> 78.325859 | Q58: Scrap | R58: X | S58: 5-A | T58: X | U58: X | V58: X | W58: 3 HAVLU + 4 KILIF + 2 ÇARŞAF (1200 DEVİR)
B59: X | C59: 39 | D59: 46129 | E59: 2950 | F59: 4504 | G59: =(+(F59-E59)/E59*100) -> 52.677966 | H59: 2830 | I59: =(+(H59-E59)/E59*100) -> -4.0677966 | J59: 0.655 | K59: 95 | L59: 1552 | M59: 0 | N59: =+J59*((60)*H$5*1000/((G59-I59)*E59)) -> 2.1129032 | O59: =+K59*(60)*H$5*1000/((G59-I59)*E59) -> 306.45161 | P59: =+L59/(F59-H59)*100 -> 92.712067 | Q59: Scrap | R59: X | S59: 5-A | T59: X | U59: X | V59: X | W59: 6 HAVLU + 4 KILIF + 2 ÇARŞAF (1100 DEVİR) 23-25 DERECE
B60: X | C60: 40 | D60: 46129 | E60: 3185 | F60: 5000 | G60: =(+(F60-E60)/E60*100) -> 56.985871 | H60: 3195 | I60: =(+(H60-E60)/E60*100) -> 0.31397174 | J60: 0.672 | K60: 96 | L60: 1702 | M60: 0 | N60: =+J60*((60)*H$5*1000/((G60-I60)*E60)) -> 2.0104155 | O60: =+K60*(60)*H$5*1000/((G60-I60)*E60) -> 287.20222 | P60: =+L60/(F60-H60)*100 -> 94.293629 | Q60: Scrap | R60: X | S60: 5-A | T60: X | U60: X | V60: X | W60: 7 HAVLU + 5 KILIF + 2 ÇARŞAF (1000 DEVİR) 23-24 DERECE
...

Sheet Components
C3: Candy Best & HMD & CHG (NEL D and Above) | AC3: CHG (NEL E) | AG3: Candy Best & HMD & CHG
C4: 7 | D4: 8 | E4: 8 (low cost) | F4: 9 | G4: 10 | H4: 11 | I4: 7 | J4: 8 | K4: 9 | L4: 10 | M4: 11 | N4: 7 | O4: 8 | P4: 9 | Q4: 10 | R4: 11 | S4: 7 | T4: 8 | U4: 9 | V4: 10 | W4: 11 | X4: 7 | Y4: 8 | Z4: 9 | AA4: 10 | AB4: 11 | AC4: 7 | AD4: 8 | AE4: 8 (low cost) | AF4: 9 | AG4: 10 | AH4: 11
C5: E | D5: E | E5: E | F5: E | G5: E | H5: E | I5: D | J5: D | K5: D | L5: D | M5: D | N5: C | O5: C | P5: C | Q5: C | R5: C | S5: B | T5: B | U5: B | V5: B | W5: B | X5: A | Y5: A | Z5: A | AA5: A | AB5: A | AC5: E | AD5: E | AE5: E | AF5: E
C6: A+ | D6: A+ | E6: A+ | F6: A+ | G6: A+ | H6: A+ | I6: A++ | J6: A++ | K6: A++ | L6: A++ | M6: A++ | N6: A+++ | O6: A+++ | P6: A+++ | Q6: A+++ | R6: A+++ | S6: A+++ | T6: A+++ | U6: A+++ | V6: A+++ | W6: A+++ | X6: A+++ | Y6: A+++ | Z6: A+++ | AA6: A+++ | AB6: A+++ | AC6: A+ | AD6: A+ | AE6: A+ | AF6: A+ | AG6: A++ | AH6: A++
B7: Basement | C7: 91404898* | D7: 91404898* | E7: 91404898* | F7: 91404898* | G7: 91404898* | H7: 91404898* | I7: 91404898* | J7: 91404898* | K7: 91404898* | L7: 91404898** | M7: 91404898** | N7: 70018390 | O7: 70018390 | P7: 70018390 | Q7: 91404898** | R7: 91404898** | S7: 91404898** | T7: 91404898** | U7: 91404898** | AC7: 91404898* | AD7: 91404898* | AE7: 91404898* | AF7: 91404898* | AG7: 91404898* | AH7: 91404898*
B8: Evaporator | C8: 70033701 70005429 70053055 | D8: 70033701 70005429 70053055 | E8: 70033701 70005429 70053055 | F8: 70033701 70005429 70053055 | G8: 70033701 70005429 70053055 | H8: 70033701 70005429 70053055 | I8: 70033701 70005429 70053055 | J8: 70033701 70005429 70053055 | K8: 70033701 70005429 70053055 | L8: 70033701 70005429 70053055 | M8: 70033701 70005429 70053055 | N8: 70013434 | O8: 70013434 | P8: 70013434 | Q8: 40015287 | R8: 40015287 | S8: 40015287 | T8: 40015287 | U8: 40015287 | AC8: 70033701 70005429 70053055 | AD8: 70033701 70005429 70053055 | AE8: 70033701 70005429 70053055 | AF8: 70033701 70005429 70053055 | AG8: 70033701 70005429 70053055 | AH8: 70033701 70005429 70053055
B9: Condenser | C9: 70033700 70005428 70053020 | D9: 70033700 70005428 70053020 | E9: 70041311 | F9: 70033700 70005428 70053020 | G9: 70033700 70005428 70053020 | H9: 70033700 70005428 70053020 | I9: 70033700 70005428 70053020 | J9: 70033700 70005428 70053020 | K9: 70033700 70005428 70053020 | L9: 70033700 70005428 70053020 | M9: 70033700 70005428 70053020 | N9: 70013433 | O9: 70013433 | P9: 70013433 | Q9: 40015288 | R9: 40015288 | S9: 40015288 | T9: 40015288 | U9: 40015288 | AC9: 70033700 70005428 70053020 | AD9: 70033700 70005428 70053020 | AE9: 70041311 | AF9: 70033700 70005428 70053020 | AG9: 70033700 70005428 70053020 | AH9: 40015286
B10: Compressor | C10: 40015364 70080799! | D10: 40015364 70080799! | E10: 70041310 | F10: 40015364 70080799! | G10: 40015364 70080799! | H10: 40015364 70080799! | I10: 40015364 70080799! | J10: 40015364 70080799! | K10: 40015364 70080799! | L10: 40015364 70080799! | M10: 40015364 70080799! | N10: 70014569 | O10: 70014569 | P10: 70014569 | Q10: 40014855 | R10: 40014855 | S10: 40014855 | T10: 40014855 | U10: 40014855 | AC10: 40015364 70080789! | AD10: 40015364 70080789! | AE10: 40015364 70080789! | AF10: 40015364 70080789! | AG10: 40015364 70080789! | AH10: 40015364 70080789!
B11: Capillary | C11: 70042251 | D11: 70042251 | E11: 70042251 | F11: 70042251 | G11: 70031142 | H11: 70031142 | I11: 70031142 | J11: 70031142 | K11: 70031142 | L11: 70031142 | M11: 70031142 | N11: 70014572 | O11: 70014572 | P11: 70014572 | Q11: 70057614 | R11: 70057614 | S11: 70057614 | T11: 70057614 | U11: 70057614 | AC11: 40014301 | AD11: 40014301 | AE11: 70042251 | AF11: 40014301 | AG11: 70031142 | AH11: 70031142
B12: Motor | C12: 70047244 | D12: 70047244 | E12: 70047244 | F12: 70047244 | G12: 70047244 | H12: 70047244 | I12: 70047244 | J12: 70047244 | K12: 70047244 | L12: 70016632 | M12: 70016632 | N12: 70016632 | O12: 70016632 | P12: 70016632 | Q12: 70016632 | R12: 70016632 | S12: 70016632 | T12: 70016632 | U12: 70016632 | AC12: 70047244 | AD12: 70047244 | AE12: 70047244 | AF12: 70047244 | AG12: 70047244 | AH12: 70047244
B13: Rear cover | C13: 40014287 | D13: 40014287 | E13: 40014287 | F13: 40014287 | G13: 70019615*** | H13: 70019615*** | I13: 40014287 | J13: 40014287 | K13: 40014287 | L13: 70019615 | M13: 70019615 | N13: 70019615 | O13: 70019615 | P13: 70019615 | Q13: 70019615 | R13: 70019615 | S13: 70019615 | T13: 70019615 | U13: 70019615 | AC13: 40014287 | AD13: 40014287 | AE13: 40014287 | AF13: 40014287 | AG13: 70019615*** | AH13: 70019615***
B14: Compressor Fan | C14: No | D14: No | E14: No | F14: No | G14: Yes | H14: Yes | I14: Yes | J14: Yes | K14: Yes | L14: Yes | M14: Yes | N14: Yes | O14: Yes | P14: Yes | Q14: Yes | R14: Yes | S14: Yes | T14: Yes | U14: Yes | AC14: No | AD14: No | AE14: No | AF14: No | AG14: Yes | AH14: Yes
C15: * oval motor hole | E15: ** circle motor hole | G15: *** without insulation | J15: ! Highly (not homologated)
B18: Basement | J18: Evaporator | Q18: Condenser | X18: Rear cover
B19: Material Code | D19: Approved Supplier | F19: Specifecation | J19: Material Code | L19: Approved Supplier | N19: Specifecation | Q19: Material Code | S19: Approved Supplier | U19: Specifecation | X19: Material Code | Z19: Approved Supplier | AB19: Specifecation
B20: 91404898 | D20: In house | F20: All class E and 7/8/9 kg class D basement | J20: 70033701 | L20: Korel, Konveyör | N20: Al - F=3 mm | Q20: 70033700 | S20: Korel, Konveyör | U20: Al - F=2,2 mm | X20: 40014287 | Z20: Teknika | AB20: AC suitable
B21: 70018390 | D21: In house | F21: 10/11 class D and above basement | J21: 70005429 | L21: Korel, Konveyör, NBR | N21: Al - F=3 mm | Q21: 70005428 | S21: Korel, Konveyör, NBR | U21: Al - F=2,2 mm | X21: 70019615 | Z21: In house | AB21: BPM suitable
J22: 70053055 | L22: Changfa | N22: Al - F=3 mm | Q22: 70053020 | S22: Changfa | U22: Al - F=2,2 mm
J23: 70013434 | L23: Konveyör | N23: Al - F=2,7 mm | Q23: 40015286 | S23: Korel, Konveyör, NBR | U23: Al - F=2,2 mm
J24: 40015287 | L24: Korel | N24: Cu - F=2,5 mm | Q24: 70041311 | S24: Konveyör | U24: Al - F=5 mm
Q25: 70013433 | S25: Konveyör | U25: Al - F=2 mm
Q26: 40015288 | S26: Korel | U26: Cu - F=1,8 mm
B28: Compressor | J28: Capillary Assy | Q28: Motor
B29: Material Code | D29: Approved Supplier | F29: Specifecation | J29: Material Code | L29: Approved Supplier | N29: Specifecation | Q29: Material Code | S29: Approved Supplier | U29: Specifecation
B30: 40015364 | D30: Rechi | F30: 35Q073M - All class E and class D | J30: 40014301 (40014304) | L30: NBR | N30: 1,4 - 500 | Q30: 70047244 | S30: Nidec | U30: AC
B31: 70080799 | D31: Highly | F31: PSA580DV - All class E and class D | J31: 70042251 (70041311) | L31: NBR | N31: 1,4 - 1000 | Q31: 70016632 | S31: Nanyang | U31: BPM
B32: 70014569 | D32: Rechi | F32: 39Q083H - 7/8/9 kg class C | J32: 70031142 (70061287) | L32: NBR | N32: 1,3 - 1300
B33: 40014855 | D33: Rechi | F33: 39Q0T3H - 10/11 kg class C & 7/8/9 class B | J33: 70014572 (70014574) | L33: Korel, Konveyör, NBR | N33: 1,3 - 1300
B34: 70041310 | D34: Rechi | F34: 35Q53I class E 8kg low cost | J34: 70057614 (70057615) | L34: NBR | N34: 1,4 - 1900

Sheet TD info
C3: Candy Best & HMD
B4: Capacity | C4: 7 | D4: 8 | E4: 8 (low cost) | F4: 9 | G4: 10 | H4: 11 | I4: 7 | J4: 8 | K4: 9 | L4: 10 | M4: 11 | N4: 7 | O4: 8 | P4: 9 | Q4: 10 | R4: 11 | S4: 7 | T4: 8 | U4: 9 | V4: 10 | W4: 11 | X4: 7 | Y4: 8 | Z4: 9 | AA4: 10 | AB4: 11
B5: NEL Energy | C5: E | D5: E | E5: E | F5: E | G5: E | H5: E | I5: D | J5: D | K5: D | L5: D | M5: D | N5: C | O5: C | P5: C | Q5: C | R5: C | S5: B | T5: B | U5: B | V5: B | W5: B | X5: A | Y5: A | Z5: A | AA5: A | AB5: A
B6: OEL Energy | C6: A+ | D6: A+ | E6: A+ | F6: A+ | G6: A+ | H6: A+ | I6: A++ | J6: A++ | K6: A++ | L6: A++ | M6: A++ | N6: A+++ | O6: A+++ | P6: A+++ | Q6: A+++ | R6: A+++ | S6: A+++ | T6: A+++ | U6: A+++ | V6: A+++ | W6: A+++ | X6: A+++ | Y6: A+++ | Z6: A+++ | AA6: A+++ | AB6: A+++
B7: Energy Cons. kW/h 100 cycles (NEL) | C7: =ROUND(C8,0) -> 133 | D7: =ROUND(D8,0) -> 144 | E7: =ROUND(E8,0) -> 144 | F7: =ROUND(F8,0) -> 156 | G7: =ROUND(G8,0) -> 166 | H7: =ROUND(H8,0) -> 176 | I7: =ROUND(I8,0) -> 110 | J7: =ROUND(J8,0) -> 119 | ... AB7: =ROUND(AB8,0) -> 89
B8: Energy Cons. kW/h 100 cycles (NEL) | C8: =(0.24*C11+0.76*C12)*100 -> 132.88 | D8: =(0.24*D11+0.76*D12)*100 -> 144.08 | E8: =(0.24*E11+0.76*E12)*100 -> 144.08 | F8: =(0.24*F11+0.76*F12)*100 -> 155.64 | G8: =(0.24*G11+0.76*G12)*100 -> 166.4 | H8: =(0.24*H11+0.76*H12)*100 -> 176.36 | I8: =(0.24*I11+0.76*I12)*100 -> 109.52 | J8: =(0.24*J11+0.76*J12)*100 -> 118.96 | ... AB8: =(0.24*AB11+0.76*AB12)*100 -> 89.4
B9: Energy Cons. kWh/Annual (OEL) | C9: =ROUND(C10,0) -> 243 | D9: =ROUND(D10,0) -> 262 | E9: =ROUND(E10,0) -> 262 | F9: =ROUND(F10,0) -> 287 | G9: =ROUND(G10,0) -> 311 | H9: =ROUND(H10,0) -> 336 | I9: =ROUND(I10,0) -> 201 | J9: =ROUND(J10,0) -> 218 | ... AB9: =ROUND(AB10,0) -> 165
B10: Energy Cons. kWh/Annual (OEL) | C10: 243.03181 | D10: 262.44381 | E10: 262.41429 | F10: 286.64743 | G10: 311.08724 | H10: 335.7141 | I10: 201.44095 | J10: 218.33619 | K10: 235.68857 | L10: 259.86857 | M10: 276.2981 | N10: 170.12857 | O10: 187.73048 | P10: 203.94057 | Q10: 222.86095 | R10: 236.99619 | S10: 142.93105 | T10: 158.23638 | U10: 169.18762 | V10: 180.57524 | W10: 191.96762 | X10: 124.87143 | Y10: 136.75067 | Z10: 146.112 | AA10: 155.43238 | AB10: 165.22476
B11: Energy Cons. Program Cotton (0%) kW/h cycle full load | C11: 1.99 | D11: 2.14 | E11: 2.14 | F11: 2.4 | G11: 2.69 | H11: 3.01 | I11: 1.65 | J11: 1.79 | K11: 1.95 | L11: 2.29 | M11: 2.45 | N11: 1.34 | O11: 1.53 | P11: 1.7 | Q11: 1.95 | R11: 2.09 | S11: 1.13 | T11: 1.3 | U11: 1.38 | V11: 1.48 | W11: 1.58 | X11: 1 | Y11: 1.12 | Z11: 1.19 | AA11: 1.26 | AB11: 1.35
B12: Energy Cons. Program Cotton (0%) kW/h cycle half load | C12: 1.12 | D12: 1.22 | E12: 1.22 | F12: 1.29 | G12: 1.34 | H12: 1.37 | I12: 0.92 | J12: 1 | K12: 1.07 | L12: 1.08 | M12: 1.14 | N12: 0.81 | O12: 0.86 | P12: 0.91 | Q12: 0.93 | R12: 0.98 | S12: 0.67 | T12: 0.71 | U12: 0.77 | V12: 0.82 | W12: 0.87 | X12: 0.57 | Y12: 0.61 | Z12: 0.66 | AA12: 0.71 | AB12: 0.75
B13: weighted programme time (min) (NEL) | C13: 138.16 | D13: 150.4 | E13: 171.6 | F13: 167.04 | G13: 176.08 | H13: 210.04 | I13: 133 | J13: 145.4 | K13: 157.8 | L13: 184.8 | M13: 200.8 | N13: 134.4 | O13: 129.2 | P13: 142.68 | Q13: 173.8 | R13: 193.4 | S13: 130.28 | T13: 134.92 | U13: 147.8 | V13: 173.8 | W13: 193.4 | X13: 134.4 | Y13: 134.92 | Z13: 142.68 | AA13: 173.8 | AB13: 193.4
B14: Drying time Program Cotton (min) full load | C14: 202 | D14: 215 | E14: 240 | F14: 240 | G14: 265 | H14: 340 | I14: 190 | J14: 210 | K14: 230 | L14: 295 | M14: 330 | N14: 180 | O14: 190 | P14: 205 | Q14: 265 | R14: 315 | S14: 185 | T14: 198 | U14: 220 | V14: 265 | W14: 315 | X14: 180 | Y14: 198 | Z14: 205 | AA14: 265 | AB14: 315
B15: Drying time Program Cotton (min) half load | C15: 118 | D15: 130 | E15: 150 | F15: 144 | G15: 148 | H15: 169 | I15: 115 | J15: 125 | K15: 135 | L15: 150 | M15: 160 | N15: 120 | O15: 110 | P15: 123 | Q15: 145 | R15: 155 | S15: 113 | T15: 115 | U15: 125 | V15: 145 | W15: 155 | X15: 120 | Y15: 115 | Z15: 123 | AA15: 145 | AB15: 155
B16: Drying time Program Cotton (min) full load (NEL) | C16: =C14/1440 -> 0.14027778 | D16: =D14/1440 -> 0.14930556 | E16: =E14/1440 -> 0.16666667 | F16: =F14/1440 -> 0.16666667 | G16: =G14/1440 -> 0.18402778 | H16: =H14/1440 -> 0.23611111 | I16: =I14/1440 -> 0.13194444 | J16: =J14/1440 -> 0.14583333 | ... AB16: =AB14/1440 -> 0.21875
B17: Condensation efficiency class (NEL) | C17: C | D17: C | E17: C | F17: C | G17: C | H17: C | I17: B | J17: B | K17: B | L17: B | M17: B | N17: B | O17: B | P17: B | Q17: B | R17: B | S17: B | T17: B | U17: B | V17: B | W17: B | X17: B | Y17: B | Z17: B | AA17: B | AB17: B
B18: weighted condensation efficiency % | C18: 84 | D18: 84 | E18: 84 | F18: 84 | G18: 84 | H18: 84 | I18: 88 | J18: 88 | K18: 88 | L18: 88 | M18: 88 | N18: 88 | O18: 88 | P18: 88 | Q18: 88 | R18: 88 | S18: 88 | T18: 88 | U18: 88 | V18: 88 | W18: 88 | X18: 88 | Y18: 88 | Z18: 88 | AA18: 88 | AB18: 88
B19: Condensation efficiency full load % | C19: 84 | D19: 84 | E19: 84 | F19: 84 | G19: 84 | H19: 84 | I19: 88 | J19: 88 | K19: 88 | L19: 88 | M19: 88 | N19: 88 | O19: 88 | P19: 88 | Q19: 88 | R19: 88 | S19: 88 | T19: 88 | U19: 88 | V19: 88 | W19: 88 | X19: 88 | Y19: 88 | Z19: 88 | AA19: 88 | AB19: 88
B20: Condensation efficiency half load% | C20: 84 | D20: 84 | E20: 84 | F20: 84 | G20: 84 | H20: 84 | I20: 88 | J20: 88 | K20: 88 | L20: 88 | M20: 88 | N20: 88 | O20: 88 | P20: 88 | Q20: 88 | R20: 88 | S20: 88 | T20: 88 | U20: 88 | V20: 88 | W20: 88 | X20: 88 | Y20: 88 | Z20: 88 | AA20: 88 | AB20: 88
B21: Noise level (dB) | C21: 67 | D21: 67 | E21: 67 | F21: 66 | G21: 66 | H21: 66 | I21: 66 | J21: 66 | K21: 66 | L21: 64 | M21: 64 | N21: 63 | O21: 63 | P21: 63 | Q21: 63 | R21: 63 | S21: 63 | T21: 63 | U21: 63 | V21: 63 | W21: 63 | X21: 64 | Y21: 63 | Z21: 63 | AA21: 63 | AB21: 63
B22: Noise NEL class | C22: C | D22: C | E22: C | F22: C | G22: C | H22: C | I22: C | J22: C | K22: C | L22: B | M22: B | N22: B | O22: B | P22: B | Q22: B | R22: B | S22: B | T22: B | U22: B | V22: B | W22: B | X22: B | Y22: B | Z22: B | AA22: B | AB22: B
B23: Power consumption of off-mode (std. Prog full load) W | C23: 0.5 | D23: 0.5 | E23: 0.5 | F23: 0.5 | G23: 0.5 | H23: 0.5 | I23: 0.5 | J23: 0.5 | K23: 0.5 | L23: 0.5 | M23: 0.5 | N23: 0.5 | O23: 0.5 | P23: 0.5 | Q23: 0.5 | R23: 0.5 | S23: 0.5 | T23: 0.5 | U23: 0.5 | V23: 0.5 | W23: 0.5 | X23: 0.5 | Y23: 0.5 | Z23: 0.5 | AA23: 0.5 | AB23: 0.5
B24: Power consumption of left on-mode (std. Prog full load) W | C24: 0.5 | D24: 0.5 | E24: 0.5 | F24: 0.5 | G24: 0.5 | H24: 0.5 | I24: 0.5 | J24: 0.5 | K24: 0.5 | L24: 0.5 | M24: 0.5 | N24: 0.5 | O24: 0.5 | P24: 0.5 | Q24: 0.5 | R24: 0.5 | S24: 0.5 | T24: 0.5 | U24: 0.5 | V24: 0.5 | W24: 0.5 | X24: 0.5 | Y24: 0.5 | Z24: 0.5 | AA24: 0.5 | AB24: 0.5
B25: Duration of the left-on mode (min) | C25: 5 | D25: 5 | E25: 5 | F25: 5 | G25: 5 | H25: 5 | I25: 5 | J25: 5 | K25: 5 | L25: 5 | M25: 5 | N25: 5 | O25: 5 | P25: 5 | Q25: 5 | R25: 5 | S25: 5 | T25: 5 | U25: 5 | V25: 5 | W25: 5 | X25: 5 | Y25: 5 | Z25: 5 | AA25: 5 | AB25: 5
B26: Energy Cons. Program Whites (-6%) kW/h cycle full load | C26: 2.4875 | D26: 2.675 | E26: 2.675 | F26: 3 | G26: 3.3625 | H26: 3.7625 | I26: 2.0625 | J26: 2.2375 | K26: 2.4375 | L26: 2.8625 | M26: 3.0625 | N26: 1.6884 | O26: 1.9278 | P26: 2.142 | Q26: 2.457 | R26: 2.6334 | S26: 1.4238 | T26: 1.625 | U26: 1.725 | V26: 1.85 | W26: 1.975 | X26: 1.26 | Y26: 1.4 | Z26: 1.4875 | AA26: 1.575 | AB26: 1.6875
B27: Drying time Program Whites (min) full load | C27: 252.5 | D27: 268.75 | E27: 300 | F27: 300 | G27: 331.25 | H27: 425 | I27: 237.5 | J27: 262.5 | K27: 287.5 | L27: 368.75 | M27: 412.5 | N27: 228.6 | O27: 241.3 | P27: 260.35 | Q27: 336.55 | R27: 400.05 | S27: 234.95 | T27: 247.5 | U27: 275 | V27: 331.25 | W27: 393.75 | X27: 228.6 | Y27: 247.5 | Z27: 256.25 | AA27: 331.25 | AB27: 393.75
B28: Energy Cons. Program Whites (-3%) kW/h cycle full load | C28: 2.189 | D28: 2.354 | E28: 2.354 | F28: 2.64 | G28: 2.959 | H28: 3.311 | I28: 1.815 | J28: 1.969 | K28: 2.145 | L28: 2.519 | M28: 2.695 | N28: 1.474 | O28: 1.683 | P28: 1.87 | Q28: 2.145 | R28: 2.299 | S28: 1.243 | T28: 1.43 | U28: 1.518 | V28: 1.628 | W28: 1.738 | X28: 1.1 | Y28: 1.232 | Z28: 1.309 | AA28: 1.386 | AB28: 1.485
B29: Drying time Program Whites (min) full load | C29: 222.2 | D29: 236.5 | E29: 264 | F29: 264 | G29: 291.5 | H29: 374 | I29: 209 | J29: 231 | K29: 253 | L29: 324.5 | M29: 363 | N29: 207 | O29: 218.5 | P29: 235.75 | Q29: 304.75 | R29: 362.25 | S29: 212.75 | T29: 217.8 | U29: 242 | V29: 291.5 | W29: 346.5 | X29: 207 | Y29: 217.8 | Z29: 225.5 | AA29: 291.5 | AB29: 346.5
B30: Energy Cons. Program Whites (+12%) kW/h cycle full load | C30: 1.592 | D30: 1.712 | E30: 1.712 | F30: 1.92 | G30: 2.152 | H30: 2.408 | I30: 1.32 | J30: 1.432 | K30: 1.56 | L30: 1.832 | M30: 1.96 | N30: 1.072 | O30: 1.224 | P30: 1.36 | Q30: 1.56 | R30: 1.672 | S30: 0.904 | T30: 1.04 | U30: 1.104 | V30: 1.184 | W30: 1.264 | X30: 0.8 | Y30: 0.896 | Z30: 0.952 | AA30: 1.008 | AB30: 1.08
B31: Drying time Program Iron Whites (min) full load | C31: 161.6 | D31: 172 | E31: 192 | F31: 192 | G31: 212 | H31: 272 | I31: 152 | J31: 168 | K31: 184 | L31: 236 | M31: 264 | N31: 144 | O31: 152 | P31: 164 | Q31: 212 | R31: 252 | S31: 148 | T31: 158.4 | U31: 176 | V31: 212 | W31: 252 | X31: 144 | Y31: 158.4 | Z31: 164 | AA31: 212 | AB31: 252
C34: CHG
B35: Capacity | C35: 7 | D35: 8 | E35: 8 (low cost) | F35: 9 | G35: 10 | H35: 11 | I35: 7 | J35: 8 | K35: 9 | L35: 10 | M35: 11 | N35: 7 | O35: 8 | P35: 9 | Q35: 10 | R35: 11 | S35: 7 | T35: 8 | U35: 9 | V35: 10 | W35: 11 | X35: 7 | Y35: 8 | Z35: 9 | AA35: 10 | AB35: 11
B36: NEL Energy | C36: E | D36: E | E36: E | F36: E | G36: E | H36: E | I36: D | J36: D | K36: D | L36: D | M36: D | N36: C | O36: C | P36: C | Q36: C | R36: C | S36: B | T36: B | U36: B | V36: B | W36: B | X36: A | Y36: A | Z36: A | AA36: A | AB36: A
B37: OEL Energy | C37: A+ | D37: A+ | E37: A+ | F37: A+ | G37: A+ | H37: A+ | I37: A++ | J37: A++ | K37: A++ | L37: A++ | M37: A++ | N37: A+++ (A++) | O37: A+++ (A++) | P37: A+++ (A++) | Q37: A+++ (A++) | R37: A+++ (A++) | S37: A+++ | T37: A+++ | U37: A+++ | V37: A+++ | W37: A+++ | X37: A+++ | Y37: A+++ | Z37: A+++ | AA37: A+++ | AB37: A+++
B38: Energy Cons. kW/h 100 cycles (NEL) | C38: =ROUND(C39,0) -> 133 | D38: =ROUND(D39,0) -> 144 | E38: =ROUND(E39,0) -> 144 | F38: =ROUND(F39,0) -> 156 | G38: =ROUND(G39,0) -> 166 | H38: =ROUND(H39,0) -> 177 | I38: =ROUND(I39,0) -> 110 | J38: =ROUND(J39,0) -> 119 | ... AB38: =ROUND(AB39,0) -> 89
B39: Energy Cons. kW/h 100 cycles (NEL) | C39: =(0.24*C42+0.76*C43)*100 -> 132.88 | D39: =(0.24*D42+0.76*D43)*100 -> 144.08 | E39: =(0.24*E42+0.76*E43)*100 -> 144.08 | F39: =(0.24*F42+0.76*F43)*100 -> 155.64 | G39: =(0.24*G42+0.76*G43)*100 -> 166.4 | H39: =(0.24*H42+0.76*H43)*100 -> 176.6 | I39: =(0.24*I42+0.76*I43)*100 -> 109.52 | J39: =(0.24*J42+0.76*J43)*100 -> 118.96 | ... AB39: =(0.24*AB42+0.76*AB43)*100 -> 89.4
B40: Energy Cons. kWh/Annual (OEL) | C40: =ROUND(C41,0) -> 243 | D40: =ROUND(D41,0) -> 262 | E40: =ROUND(E41,0) -> 262 | F40: =ROUND(F41,0) -> 287 | G40: =ROUND(G41,0) -> 311 | H40: =ROUND(H41,0) -> 336 | I40: =ROUND(I41,0) -> 201 | J40: =ROUND(J41,0) -> 218 | ... AB40: =ROUND(AB41,0) -> 165
B41: Energy Cons. kWh/Annual (OEL) | C41: =160*(3*C42+4*C43)/7+(C54+C55)*(525600-(+C45*3+C46*4)/7*160)/120000 -> 243.03181 | D41: =160*(3*D42+4*D43)/7+(D54+D55)*(525600-(+D45*3+D46*4)/7*160)/120000 -> 262.43429 | E41: =160*(3*E42+4*E43)/7+(E54+E55)*(525600-(+E45*3+E46*4)/7*160)/120000 -> 262.41429 | F41: =160*(3*F42+4*F43)/7+(F54+F55)*(525600-(+F45*3+F46*4)/7*160)/120000 -> 286.63219 | G41: =160*(3*G42+4*G43)/7+(G54+G55)*(525600-(+G45*3+G46*4)/7*160)/120000 -> 311.08724 | H41: =160*(3*H42+4*H43)/7+(H54+H55)*(525600-(+H45*3+H46*4)/7*160)/120000 -> 336.39981 | I41: =160*(3*I42+4*I43)/7+(I54+I55)*(525600-(+I45*3+I46*4)/7*160)/120000 -> 201.44095 | J41: =160*(3*J42+4*J43)/7+(J54+J55)*(525600-(+J45*3+J46*4)/7*160)/120000 -> 218.33619 | ... AB41: =160*(3*AB42+4*AB43)/7+(AB54+AB55)*(525600-(+AB45*3+AB46*4)/7*160)/120000 -> 165.22476
B42: Energy Cons. Program Cotton (0%) kW/h cycle full load | C42: 1.99 | D42: 2.14 | E42: 2.14 | F42: 2.4 | G42: 2.69 | H42: 3.02 | I42: 1.65 | J42: 1.79 | K42: 1.95 | L42: 2.29 | M42: 2.45 | N42: 1.34 | O42: 1.53 | P42: 1.7 | Q42: 1.95 | R42: 2.09 | S42: 1.13 | T42: 1.3 | U42: 1.38 | V42: 1.48 | W42: 1.58 | X42: 1 | Y42: 1.12 | Z42: 1.19 | AA42: 1.26 | AB42: 1.35
B43: Energy Cons. Program Cotton (0%) kW/h cycle half load | C43: 1.12 | D43: 1.22 | E43: 1.22 | F43: 1.29 | G43: 1.34 | H43: 1.37 | I43: 0.92 | J43: 1 | K43: 1.07 | L43: 1.08 | M43: 1.14 | N43: 0.81 | O43: 0.86 | P43: 0.91 | Q43: 0.93 | R43: 0.98 | S43: 0.67 | T43: 0.71 | U43: 0.77 | V43: 0.82 | W43: 0.87 | X43: 0.57 | Y43: 0.61 | Z43: 0.66 | AA43: 0.71 | AB43: 0.75
B44: weighted programme time (min) (NEL) | C44: =(+C45*0.24+C46*0.76) -> 138.16 | D44: =(+D45*0.24+D46*0.76) -> 156.6 | E44: =(+E45*0.24+E46*0.76) -> 171.6 | F44: =(+F45*0.24+F46*0.76) -> 175.64 | G44: =(+G45*0.24+G46*0.76) -> 176.08 | H44: =(+H45*0.24+H46*0.76) -> 210.04 | I44: =(+I45*0.24+I46*0.76) -> 133 | J44: =(+J45*0.24+J46*0.76) -> 145.4 | ... AB44: =(+AB45*0.24+AB46*0.76) -> 193.4
...

Sheet OLD TD info
D3: Product | E3: 1 | K3: 2 | P3: 3 | S3: 4 | V3: 5 | AA3: 6 | AF3: 7 | AM3: 8
E4: Heat Pump | K4: Heat Pump | P4: Heat Pump EOLO- OLD- STEP1 | S4: Heat Pump EOLO- STEP 2 | V4: HaierMatching HeatPump | AA4: HaierMatching HeatPump | AF4: Candy Best | AM4: Candy Best
D5: Capacity | E5: 7 | F5: 8 | G5: 8.01 | H5: 9 | I5: 10 | J5: 11 | K5: 7 | L5: 8 | M5: 9 | N5: 10 | O5: 11 | P5: 7 | Q5: 8 | R5: 9 | S5: 7 | T5: 8 | U5: 9 | V5: 7 | W5: 8 | X5: 9 | Y5: 10 | Z5: 11 | AB5: 8 | AC5: 9 | AD5: 10 | AE5: 11 | AG5: 8 | AH5: 9 | AI5: 10 | AJ5: 10 | AK5: 11* | AL5: 11 | AM5: 8 | AN5: 8 | AO5: 9 | AP5: 10 | AQ5: 11
D6: Class | E6: A+ | F6: A+ | G6: A+ Entry Level | H6: A+ | I6: A+ | J6: A+ | K6: A++ | L6: A++ | M6: A++ | N6: A++ | O6: A++ | P6: A+++ | Q6: A+++ | R6: A+++ | S6: A+++ | T6: A+++ | U6: A+++ | V6: A++ | W6: A++ | X6: A++ | Y6: A++ | Z6: A++ | AB6: A+++ | AC6: A+++ | AD6: A+++ | AE6: A+++ | AH6: A++ | AI6: A++ | AJ6: A++ | AK6: A+ | AL6: A++ | AM6: A+++ | AN6: A+++ | AO6: A+++ | AP6: A+++ | AQ6: A+++
D7: NEL Energy | E7: E | F7: E | G7: E | H7: E | I7: E | J7: E | K7: E | L7: E | M7: E | N7: E | O7: E | P7: C | Q7: C | R7: C | S7: C | T7: C | U7: C | V7: E | W7: E | X7: E | Y7: E | Z7: E | AB7: C | AC7: C | AD7: C | AE7: C | AH7: D | AI7: E | AJ7: D | AK7: E | AL7: D | AM7: B | AN7: C | AO7: C | AP7: C | AQ7: C
D8: Energy Cons. kW/h annual (OEL) | E8: 245 | F8: 273 | G8: 264 | H8: 289 | I8: 309 | J8: 328 | K8: 211 | L8: 236 | M8: 259 | N8: 282 | O8: 304 | P8: 159 | Q8: 177 | R8: 194 | S8: 159 | T8: 177 | U8: 194 | V8: 211 | W8: 236 | X8: 259 | Y8: 282 | Z8: 304 | AB8: 177 | AC8: 194 | AD8: 211 | AE8: 228 | AH8: 237 | AI8: 282 | AJ8: 260 | AK8: 345 | AL8: 276 | AM8: 159 | AN8: 177 | AO8: 194 | AP8: 211 | AQ8: 228
D9: Energy Cons. kW/h annual (OEL) | E9: 244.8 | F9: 273.1 | G9: 263.3 | H9: 289.6 | I9: 309.3 | J9: 328.4 | K9: 211.4 | L9: 235.9 | M9: 258.9 | N9: 282 | O9: 303.9 | P9: 159 | Q9: 176.8 | R9: 193.9 | S9: 159 | T9: 176.8 | U9: 193.9 | V9: 211.4 | W9: 235.9 | X9: 258.9 | Y9: 282 | Z9: 303.9 | AB9: 176.8 | AC9: 193.9 | AD9: 211 | AE9: 227.9 | AH9: 236.9 | AI9: 282 | AJ9: 260.6 | AK9: 345.8 | AL9: 275.9 | AM9: 159.5 | AN9: 176.8 | AO9: 193.9 | AP9: 211 | AQ9: 227.9
D10: Energy Cons. kW/h 100 cycles (NEL) | E10: =ROUND(E11,0) -> 133 | F10: =ROUND(F11,0) -> 144 | G10: =ROUND(G11,0) -> 144 | H10: =ROUND(H11,0) -> 156 | I10: =ROUND(I11,0) -> 166 | J10: =ROUND(J11,0) -> 177 | K10: =ROUND(K11,0) -> 115 | L10: =ROUND(L11,0) -> 128 | ... AQ10: =ROUND(AQ11,0) -> 120
D11: Energy Cons. kW/h 100 cycles (NEL) | E11: 132.84 | F11: 144.08 | G11: 144.08 | H11: 155.8 | I11: 166.2 | J11: 176.88 | K11: 115 | L11: 128.4 | M11: 140 | N11: 150.3 | O11: 159.3 | P11: 86.8 | Q11: 95.6 | R11: 104.3 | S11: 86.8 | T11: 95.6 | U11: 104.3 | V11: 115 | W11: 128.4 | X11: 140 | Y11: 150.3 | Z11: 159.3 | AB11: 95.6 | AC11: 104.3 | AD11: 111.6 | AE11: 119.7 | AH11: 128.12 | AI11: 150.28 | AJ11: 137.28 | AK11: 176.8 | AL11: 144.96 | AM11: 85.16 | AN11: 95.64 | AO11: 104.28 | AP11: 111.56 | AQ11: 119.68
D12: Energy Cons. Program Cotton (0%) kW/h cycle full load | E12: 2.02 | F12: 2.14 | G12: 2.14 | H12: 2.47 | I12: 2.65 | J12: 2.81 | K12: 1.72 | L12: 1.93 | M12: 2.16 | N12: 2.43 | O12: 2.71 | P12: 1.24 | Q12: 1.42 | R12: 1.59 | S12: 1.24 | T12: 1.42 | U12: 1.59 | V12: 1.72 | W12: 1.93 | X12: 2.16 | Y12: 2.43 | Z12: 2.71 | AB12: 1.42 | AC12: 1.59 | AD12: 1.83 | AE12: 2.01 | AH12: 1.95 | AI12: 2.43 | AJ12: 2.3 | AK12: 3.25 | AL12: 2.43 | AM12: 1.3 | AN12: 1.42 | AO12: 1.59 | AP12: 1.83 | AQ12: 2.01
D13: Energy Cons. Program Cotton (0%) kW/h cycle half load | E13: 1.11 | F13: 1.22 | G13: 1.22 | H13: 1.27 | I13: 1.35 | J13: 1.44 | K13: 0.97 | L13: 1.08 | M13: 1.16 | N13: 1.21 | O13: 1.24 | P13: 0.75 | Q13: 0.81 | R13: 0.87 | S13: 0.75 | T13: 0.81 | U13: 0.87 | V13: 0.97 | W13: 1.08 | X13: 1.16 | Y13: 1.21 | Z13: 1.24 | AB13: 0.81 | AC13: 0.87 | AD13: 0.89 | AE13: 0.94 | AH13: 1.07 | AI13: 1.21 | AJ13: 1.08 | AK13: 1.3 | AL13: 1.14 | AM13: 0.71 | AN13: 0.81 | AO13: 0.87 | AP13: 0.89 | AQ13: 0.94
D14: weighted programme time (min) (OEL) | E14: 154 | F14: 173.57143 | G14: 188.57143 | H14: 196.57143 | I14: 207.42857 | J14: 246.57143 | K14: 154 | L14: 173.57143 | M14: 196.57143 | N14: 207.42857 | O14: 246.57143 | P14: 145.71429 | Q14: 159.28571 | R14: 183.57143 | S14: 145.71429 | T14: 144.28571 | U14: 165.71429 | V14: 154 | W14: 166.42857 | X14: 185.14286 | Y14: 198.14286 | Z14: 242.28571 | AB14: 147.14286 | AC14: 158.14286 | AD14: 196.42857 | AE14: 223.57143 | AH14: 175.71429 | AI14: 198.14286 | AJ14: 212.14286 | AK14: 246.57143 | AL14: 232.85714 | AM14: 150.57143 | AN14: 147.14286 | AO14: 158.14286 | AP14: 196.42857 | AQ14: 223.57143
D15: weighted programme time (min) (NEL) | E15: 138.16 | F15: 156.6 | G15: 171.6 | H15: 175.64 | I15: 183.48 | J15: 212.44 | K15: 138.16 | L15: 156.6 | M15: 175.64 | N15: 183.48 | O15: 212.44 | P15: 134.4 | Q15: 144.2 | R15: 166.6 | S15: 134.4 | T15: 129.2 | U15: 147.8 | V15: 138.16 | W15: 150.4 | X15: 167.04 | Y15: 176.08 | Z15: 210.04 | AB15: 130.36 | AC15: 142.68 | AD15: 173.8 | AE15: 193.4 | AH15: 157.8 | AI15: 176.08 | AJ15: 184.8 | AK15: 212.44 | AL15: 200.8 | AM15: 134.92 | AN15: 130.36 | AO15: 142.68 | AP15: 173.8 | AQ15: 193.4
D16: Drying time Program Cotton (min) full load | E16: 202 | F16: 225 | G16: 240 | H16: 260 | I16: 280 | J16: 350 | K16: 202 | L16: 225 | M16: 260 | N16: 280 | O16: 350 | P16: 180 | Q16: 205 | R16: 235 | S16: 180 | T16: 190 | U16: 220 | V16: 202 | W16: 215 | X16: 240 | Y16: 265 | Z16: 340 | AB16: 198 | AC16: 205 | AD16: 265 | AE16: 315 | AH16: 230 | AI16: 265 | AJ16: 295 | AK16: 350 | AL16: 330 | AM16: 198 | AN16: 198 | AO16: 205 | AP16: 265 | AQ16: 315
D17: Drying time Program Cotton (min) half load | E17: 118 | F17: 135 | G17: 150 | H17: 149 | I17: 153 | J17: 169 | K17: 118 | L17: 135 | M17: 149 | N17: 153 | O17: 169 | P17: 120 | Q17: 125 | R17: 145 | S17: 120 | T17: 110 | U17: 125 | V17: 118 | W17: 130 | X17: 144 | Y17: 148 | Z17: 169 | AB17: 109 | AC17: 123 | AD17: 145 | AE17: 155 | AH17: 135 | AI17: 148 | AJ17: 150 | AK17: 169 | AL17: 160 | AM17: 115 | AN17: 109 | AO17: 123 | AP17: 145 | AQ17: 155
D18: Drying time Program Cotton (min) full load (NEL) | E18: 0.14027778 | F18: 0.15625 | G18: 0.16666667 | H18: 0.18055556 | I18: 0.19444444 | J18: 0.24305556 | K18: 0.14027778 | L18: 0.15625 | M18: 0.18055556 | N18: 0.19444444 | O18: 0.24305556 | P18: 0.125 | Q18: 0.14236111 | R18: 0.16319444 | S18: 0.125 | T18: 0.13194444 | U18: 0.15277778 | V18: 0.14027778 | W18: 0.14930556 | X18: 0.16666667 | Y18: 0.18402778 | Z18: 0.23611111 | AB18: 0.1375 | AC18: 0.14236111 | AD18: 0.18402778 | AE18: 0.21875 | AH18: 0.15972222 | AI18: 0.18402778 | AJ18: 0.20486111 | AK18: 0.24305556 | AL18: 0.22916667 | AM18: 0.1375 | AN18: 0.1375 | AO18: 0.14236111 | AP18: 0.18402778 | AQ18: 0.21875
D19: Condensation efficiency class (OEL) | E19: B | F19: B | G19: B | H19: B | I19: B | J19: B | K19: B | L19: B | M19: B | N19: B | O19: B | P19: A | Q19: A | R19: A | S19: A | T19: A | U19: A | V19: A | W19: A | X19: A | Y19: A | Z19: A | AB19: A | AC19: A | AD19: A | AE19: A | AH19: B | AI19: B | AJ19: B | AK19: B | AL19: B | AM19: A | AN19: A | AO19: A | AP19: A | AQ19: A
D20: Condensation efficiency class (NEL) | E20: C | F20: C | G20: C | H20: C | I20: C | J20: C | K20: C | L20: C | M20: C | N20: C | O20: C | P20: B | Q20: B | R20: B | S20: B | T20: B | U20: B | V20: B | W20: B | X20: B | Y20: B | Z20: B | AB20: B | AC20: B | AD20: B | AE20: B | AH20: B | AI20: B | AJ20: B | AK20: B | AL20: B | AM20: B | AN20: B | AO20: B | AP20: B | AQ20: B
D21: weighted condensation efficiency % | E21: 84 | F21: 84 | G21: 84 | H21: 84 | I21: 84 | J21: 84 | K21: 84 | L21: 84 | M21: 84 | N21: 84 | O21: 84 | P21: 91 | Q21: 91 | R21: 91 | S21: 91 | T21: 91 | U21: 91 | V21: 91 | W21: 91 | X21: 91 | Y21: 91 | Z21: 91 | AB21: 91 | AC21: 91 | AD21: 91 | AE21: 91 | AH21: 88 | AI21: 88 | AJ21: 88 | AK21: 88 | AL21: 88 | AM21: 91 | AN21: 91 | AO21: 91 | AP21: 91 | AQ21: 91
D22: Condensation efficiency full load % | E22: 84 | F22: 84 | G22: 84 | H22: 84 | I22: 84 | J22: 84 | K22: 84 | L22: 84 | M22: 84 | N22: 84 | O22: 84 | P22: 91 | Q22: 91 | R22: 91 | S22: 91 | T22: 91 | U22: 91 | V22: 91 | W22: 91 | X22: 91 | Y22: 91 | Z22: 91 | AB22: 91 | AC22: 91 | AD22: 91 | AE22: 91 | AH22: 88 | AI22: 88 | AJ22: 88 | AK22: 88 | AL22: 88 | AM22: 91 | AN22: 91 | AO22: 91 | AP22: 91 | AQ22: 91
D23: Condensation efficiency half load% | E23: 84 | F23: 84 | G23: 84 | H23: 84 | I23: 84 | J23: 84 | K23: 84 | L23: 84 | M23: 84 | N23: 84 | O23: 84 | P23: 91 | Q23: 91 | R23: 91 | S23: 91 | T23: 91 | U23: 91 | V23: 91 | W23: 91 | X23: 91 | Y23: 91 | Z23: 91 | AB23: 91 | AC23: 91 | AD23: 91 | AE23: 91 | AH23: 88 | AI23: 88 | AJ23: 88 | AK23: 88 | AL23: 88 | AM23: 91 | AN23: 91 | AO23: 91 | AP23: 91 | AQ23: 91
D24: Noise level (dB) | E24: 67 | F24: 67 | G24: 67 | H24: 66 | I24: 66 | J24: 66 | K24: 67 | L24: 67 | M24: 66 | N24: 66 | O24: 66 | P24: 69 | Q24: 69 | R24: 69 | S24: 64 | T24: 64 | U24: 64 | V24: 66 | W24: 66 | X24: 66 | Y24: 66 | Z24: 66 | AB24: 64 | AC24: 64 | AD24: 64 | AE24: 64 | AH24: 66 | AI24: 66 | AJ24: 64 | AK24: 66 | AL24: 64 | AM24: 63 | AN24: 63 | AO24: 63 | AP24: 63 | AQ24: 63
D25: Noise NEL class | E25: C | F25: C | G25: C | H25: C | I25: C | J25: C | K25: C | L25: C | M25: C | N25: C | O25: C | P25: D | Q25: D | R25: D | S25: B | T25: B | U25: B | V25: C | W25: C | X25: C | Y25: C | Z25: C | AB25: B | AC25: B | AD25: B | AE25: B | AH25: C | AI25: C | AJ25: B | AK25: C | AL25: B | AM25: B | AN25: B | AO25: B | AP25: B | AQ25: B
D26: Power consumption of off-mode (std. Prog full load) W | E26: 0.5 | F26: 0.5 | G26: 0.5 | H26: 0.5 | I26: 0.5 | J26: 0.5 | K26: 0.5 | L26: 0.5 | M26: 0.5 | N26: 0.5 | O26: 0.5 | P26: 0.5 | Q26: 0.5 | R26: 0.5 | S26: 0.5 | T26: 0.5 | U26: 0.5 | V26: 0.5 | W26: 0.5 | X26: 0.5 | Y26: 0.5 | Z26: 0.5 | AB26: 0.5 | AC26: 0.5 | AD26: 0.5 | AE26: 0.5 | AH26: 0.5 | AI26: 0.5 | AJ26: 0.5 | AK26: 0.5 | AL26: 0.5 | AM26: 0.5 | AN26: 0.5 | AO26: 0.5 | AP26: 0.5 | AQ26: 0.5
D27: Power consumption of left on-mode (std. Prog full load) W | E27: 0.5 | F27: 0.5 | G27: 0.5 | H27: 0.5 | I27: 0.5 | J27: 0.5 | K27: 0.5 | L27: 0.5 | M27: 0.5 | N27: 0.5 | O27: 0.5 | P27: 0.5 | Q27: 0.5 | R27: 0.5 | S27: 0.5 | T27: 0.5 | U27: 0.5 | V27: 0.5 | W27: 0.5 | X27: 0.5 | Y27: 0.5 | Z27: 0.5 | AB27: 0.5 | AC27: 0.5 | AD27: 0.5 | AE27: 0.5 | AH27: 0.5 | AI27: 0.5 | AJ27: 0.5 | AK27: 0.5 | AL27: 0.5 | AM27: 0.5 | AN27: 0.5 | AO27: 0.5 | AP27: 0.5 | AQ27: 0.5
D28: Duration of the left-on mode (min) | E28: 5 | F28: 5 | G28: 5 | H28: 5 | I28: 5 | J28: 5 | K28: 5 | L28: 5 | M28: 5 | N28: 5 | O28: 5 | P28: 5 | Q28: 5 | R28: 5 | S28: 5 | T28: 5 | U28: 5 | V28: 5 | W28: 5 | X28: 5 | Y28: 5 | Z28: 5 | AB28: 5 | AC28: 5 | AD28: 5 | AE28: 5 | AH28: 5 | AI28: 5 | AJ28: 5 | AK28: 5 | AL28: 5 | AM28: 5 | AN28: 5 | AO28: 5 | AP28: 5 | AQ28: 5
D29: Energy Cons. Program Whites (-6%) kW/h cycle full load | E29: 2.525 | F29: 2.875 | G29: 2.98 | H29: 3.2 | I29: 3.8125 | J29: 4.175 | K29: 2.15 | L29: 2.4125 | M29: 2.7 | N29: 3.0375 | O29: 3.3875 | P29: 1.5624 | Q29: 1.7892 | R29: 2.0034 | S29: 1.5624 | T29: 1.7892 | U29: 2.0034 | V29: 2.15 | W29: 2.4125 | X29: 2.7 | Y29: 3.0375 | Z29: 3.3875 | AB29: 1.7892 | AC29: 2.0034 | AD29: NA | AE29: NA | AH29: 2.4375 | AI29: 3.0375 | AJ29: 2.875 | AK29: 4.0625 | AL29: 3.0375 | AM29: 1.625 | AN29: 1.775 | AO29: 1.9875 | AP29: 2.2875 | AQ29: 2.5125
D30: Drying time Program Whites (min) full load | E30: 252.5 | F30: 281.25 | G30: 300 | H30: 325 | I30: 350 | J30: 437.5 | K30: 252.5 | L30: 281.25 | M30: 325 | N30: 350 | O30: 437.5 | P30: 228.6 | Q30: 260.35 | R30: 298.45 | S30: 228.6 | T30: 241.3 | U30: 279.4 | V30: 252.5 | W30: 268.75 | X30: 300 | Y30: 331.25 | Z30: 437.5 | AB30: 251.46 | AC30: 260.35 | AD30: NA | AE30: NA | AH30: 287.5 | AI30: 331.25 | AJ30: 368.75 | AK30: 437.5 | AL30: 412.5 | AM30: 247.5 | AN30: 247.5 | AO30: 256.25 | AP30: 331.25 | AQ30: 393.75
D31: Energy Cons. Program Whites (-3%) kW/h cycle full load | E31: 2.222 | F31: 2.53 | G31: 2.7 | H31: 2.816 | I31: 3.355 | J31: 3.674 | K31: 1.892 | L31: 2.123 | M31: 2.376 | N31: 2.673 | O31: 2.981 | P31: 1.364 | Q31: 1.562 | R31: 1.749 | S31: 1.364 | T31: 1.562 | U31: 1.749 | V31: 1.892 | W31: 2.123 | X31: 2.376 | Y31: 2.673 | Z31: 2.981 | AB31: 1.562 | AC31: 1.749 | AD31: NA | AE31: NA | AH31: 2.145 | AI31: 2.673 | AJ31: 2.53 | AK31: 3.575 | AL31: 2.673 | AM31: 1.43 | AN31: 1.562 | AO31: 1.749 | AP31: 2.013 | AQ31: 2.211
D32: Drying time Program Whites (min) full load | E32: 222.2 | F32: 247.5 | G32: 265 | H32: 286 | I32: 308 | J32: 385 | K32: 222.2 | L32: 247.5 | M32: 286 | N32: 308 | O32: 385 | P32: 207 | Q32: 235.75 | R32: 270.25 | S32: 207 | T32: 218.5 | U32: 253 | V32: 222.2 | W32: 236.5 | X32: 264 | Y32: 291.5 | Z32: 385 | AB32: 227.7 | AC32: 235.75 | AD32: NA | AE32: NA | AH32: 253 | AI32: 291.5 | AJ32: 324.5 | AK32: 385 | AL32: 363 | AM32: 217.8 | AN32: 217.8 | AO32: 225.5 | AP32: 291.5 | AQ32: 346.5
D33: Energy Cons. Program Whites (+12%) kW/h cycle full load | E33: 1.616 | F33: 1.84 | G33: 1.94 | H33: 2.048 | I33: 2.44 | J33: 2.672 | K33: 1.376 | L33: 1.544 | M33: 1.728 | N33: 1.944 | O33: 2.168 | P33: 0.992 | Q33: 1.136 | R33: 1.272 | S33: 0.992 | T33: 1.136 | U33: 1.272 | V33: 1.376 | W33: 1.544 | X33: 1.728 | Y33: 1.944 | Z33: 2.168 | AB33: 1.136 | AC33: 1.272 | AD33: NA | AE33: NA | AH33: 1.56 | AI33: 1.944 | AJ33: 1.84 | AK33: 2.6 | AL33: 1.944 | AM33: 1.04 | AN33: 1.136 | AO33: 1.272 | AP33: 1.464 | AQ33: 1.608
D34: Drying time Program Iron Whites (min) full load | E34: 161.6 | F34: 180 | G34: 198 | H34: 208 | I34: 224 | J34: 280 | K34: 161.6 | L34: 180 | M34: 208 | N34: 224 | O34: 280 | P34: 144 | Q34: 164 | R34: 188 | S34: 144 | T34: 152 | U34: 176 | V34: 161.6 | W34: 172 | X34: 192 | Y34: 212 | Z34: 280 | AB34: 158.4 | AC34: 164 | AD34: NA | AE34: NA | AH34: 184 | AI34: 212 | AJ34: 236 | AK34: 280 | AL34: 264 | AM34: 158.4 | AN34: 158.4 | AO34: 164 | AP34: 212 | AQ34: 252
I37: Program 1 (-6% sun) --> whites + simbolo perfect home
I38: Program 2 (-3%) --> whites + simbolo armadio
I39: Program 3 (0%) --> cotton + simbolino norma gruccia
I40: Program iron dry (+12%) --> whites + simbolo ferro da stiro
E43: 9 | G43: 10
E44: HP SLIM / BUILT-IN Russia
D45: Capacity | E45: 6 | F45: 7 | G45: 6 | H45: 7
D46: Class | E46: A+ | F46: A+ | G46: A++ | H46: A++
...
